<?xml version="1.0"?>
<robot name="vacumm_robot" xmlns:xacro="https://www.ros.org/wiki/xacro" >
    
  <material name="black">
    <color rgba="0.0 0.0 0.0 1.0"/>
  </material>
  <material name="blue">
    <color rgba="0.203125 0.23828125 0.28515625 1.0"/>
  </material>
  <material name="green">
    <color rgba="0.0 0.8 0.0 1.0"/>
  </material>
  <material name="grey">
    <color rgba="0.2 0.2 0.2 1.0"/>
  </material>
  <material name="orange">
    <color rgba="1.0 0.423529411765 0.0392156862745 1.0"/>
  </material>
  <material name="brown">
    <color rgba="0.870588235294 0.811764705882 0.764705882353 1.0"/>
  </material>
  <material name="red">
    <color rgba="0.80078125 0.12890625 0.1328125 1.0"/>
  </material>
  <material name="white">
    <color rgba="1.0 1.0 1.0 1.0"/>
  </material>  
  
  <gazebo reference="base_link">
        <material>Gazebo/White</material>
        <turnGravityOff>false</turnGravityOff>
    </gazebo>
    <gazebo reference="left_Wheel_link">
        <mu1 value="1.0"/>
        <mu2 value="1.0"/>
        <kp value="600000"/>
        <kd value="3"/>
        <fdir1 value="1 0 0"/>
        <material>Gazebo/Grey</material>
        <turnGravityOff>false</turnGravityOff>
    </gazebo>
    <gazebo reference="right_wheel_link">
        <mu1 value="1.0"/>
        <mu2 value="1.0"/>
        <kp value="600000"/>
        <kd value="3"/>
        <fdir1 value="1 0 0"/>
        <material>Gazebo/Grey</material>
        <turnGravityOff>false</turnGravityOff>
    </gazebo>

    <gazebo>
        <plugin name="gazebo_ros_control" filename="libgazebo_ros_control.so">
            <legacyMode>false</legacyMode>

        </plugin>
    </gazebo>
    
  <link name="base_link">
    <!-- pose and inertial -->
    <pose>0 0 0.1 0 0 0</pose>
    
    <inertial>
      <mass value="2"/>
      <origin rpy="0 0 0" xyz="0 0 0"/>
      <inertia ixx="0.026667" ixy="0" ixz="0" iyy="0.026667" iyz="0" izz="0.04"/>
    </inertial>
    
    <collision name="collision_chassis">
      <geometry>
        <cylinder radius="0.2" length="0.2"/>
      </geometry>
    </collision>
    
    <visual name="chassis">
      <origin rpy="0 0 0" xyz="0 0 0"/>
      <geometry>
        <cylinder radius="0.2" length="0.2"/>
      </geometry>
      <material name="blue"/>
    </visual>

    <visual name="kinect">
      <origin rpy="0 0 0" xyz="0.08 0 0.12"/>
      <geometry>
        <box size="0.05 0.05 0.05"/>
      </geometry>
      <material name="blue"/>
    </visual>
    
    <!-- caster front -->
    <collision name="caster_front_collision">
      <origin rpy=" 0 0 0" xyz="0.18 0 -0.143"/>
      <geometry>
        <sphere radius="0.02"/>
      </geometry>
      <surface>
        <friction>
          <ode>
            <mu>0</mu>
            <mu2>0</mu2>
            <slip1>1.0</slip1>
            <slip2>1.0</slip2>
          </ode>
        </friction>
      </surface>
    </collision>
   


    <!-- caster front -->
    <collision name="caster_back_collision">
      <origin rpy=" 0 0 0" xyz="-0.18 0 -0.143"/>
      <geometry>
        <sphere radius="0.02"/>
      </geometry>
      <surface>
        <friction>
          <ode>5
            <mu>0</mu>
            <mu2>0</mu2>
            <slip1>1.0</slip1>
            <slip2>1.0</slip2>
          </ode>
        </friction>
      </surface>
    </collision>
    
    </link>


    
  
  <!-- Create wheel right -->  
    
  <link name="right_wheel_link">    
    <inertial>
      <mass value="0.2"/>
      <origin rpy="0 1.5707 1.5707" xyz="0 0 0"/>
      <inertia ixx="0.00052666666" ixy="0" ixz="0" iyy="0.00052666666" iyz="0" izz="0.001"/>
    </inertial>
    
    <collision name="link_right_wheel_collision">
      <origin rpy="0 1.5707 1.5707" xyz="0 0 0" />
      <geometry>
        <cylinder length="0.01" radius="0.04"/>
      </geometry>
    </collision>
    
    <visual name="link_right_wheel_visual">
      <origin rpy="0 1.5707 1.5707" xyz="0 0 0"/>
      <geometry>
        <cylinder length="0.01" radius="0.04"/>
      </geometry>      
    </visual>
    
  </link>
    
  <!--   Joint for right wheel  -->
  <joint name="right_wheel_joint" type="continuous">
    <origin rpy="0 0 0" xyz="0 0.21 -0.125"/>
    <child link="right_wheel_link" />
    <parent link="base_link"/>
    <axis rpy="0 0 0" xyz="0 1 0"/>
    <limit effort="10000" velocity="1000"/>
    <joint_properties damping="1.0" friction="1.0" />
  </joint>  
    
  <!-- Left Wheel link -->
    
  <link name="left_wheel_link">    
    <inertial>
      <mass value="0.2"/>
      <origin rpy="0 1.5707 1.5707" xyz="0 0 0"/>
      <inertia ixx="0.00052666666" ixy="0" ixz="0" iyy="0.00052666666" iyz="0" izz="0.001"/>
    </inertial>
    
    <collision name="link_left_wheel_collision">
      <origin rpy="0 1.5707 1.5707" xyz="0 0 0" />
      <geometry>
       <cylinder length="0.01" radius="0.04"/>
      </geometry>
    </collision>
    
    <visual name="link_left_wheel_visual">
      <origin rpy="0 1.5707 1.5707" xyz="0 0 0"/>
      <geometry>
        <cylinder length="0.01" radius="0.04"/>
      </geometry>      
    </visual>
    
  </link>
    
  <!--   Joint for right wheel  -->
  <joint name="left_wheel_joint" type="continuous">
    <origin rpy="0 0 0" xyz="0 -0.21 -0.125"/>
    <child link="left_wheel_link" />
    <parent link="base_link"/>
    <axis rpy="0 0 0" xyz="0 1 0"/>
    <limit effort="10000" velocity="1000"/>
    <joint_properties damping="1.0" friction="1.0" />
  </joint>    
  
  <transmission name="left_wheel_joint_trans" type="SimpleTransmission">
        <type>transmission_interface/SimpleTransmission</type>
        <joint name="left_wheel_joint">
            <hardwareInterface>hardware_interface/VelocityJointInterface</hardwareInterface>
        </joint>
        <actuator name="left_wheel_joint_motor">
            <hardwareInterface>hardware_interface/VelocityJointInterface</hardwareInterface>
            <mechanicalReduction>1</mechanicalReduction>
        </actuator>
    </transmission>

    <transmission name="right_wheel_joint_trans" type="SimpleTransmission">
        <type>transmission_interface/SimpleTransmission</type>
        <joint name="right_wheel_joint">
            <hardwareInterface>hardware_interface/VelocityJointInterface</hardwareInterface>
        </joint>
        <actuator name="right_wheel_joint_motor">
            <hardwareInterface>hardware_interface/VelocityJointInterface</hardwareInterface>
            <mechanicalReduction>1</mechanicalReduction>
        </actuator>
    </transmission>
</robot>