<?xml version="1.0"?>
<robot name="vacumm_robot" xmlns:xacro="http://www.ros.org/wiki/xacro">
    <material name="green">
        <color rgba="0.0 0.8 0.0 1.0"/>
    </material>

    <gazebo reference="base_link">
        <material>Gazebo/White</material>
        <turnGravityOff>false</turnGravityOff>
    </gazebo>
    <gazebo reference="left_Wheel_link">
        <mu1 value="1.0"/>
        <mu2 value="1.0"/>
        <kp value="600000"/>
        <kd value="3"/>
        <fdir1 value="1 0 0"/>
        <material>Gazebo/Grey</material>
        <turnGravityOff>false</turnGravityOff>
    </gazebo>
    <gazebo reference="right_wheel_link">
        <mu1 value="1.0"/>
        <mu2 value="1.0"/>
        <kp value="600000"/>
        <kd value="3"/>
        <fdir1 value="1 0 0"/>
        <material>Gazebo/Grey</material>
        <turnGravityOff>false</turnGravityOff>
    </gazebo>

    <gazebo>
        <plugin name="gazebo_ros_control" filename="libgazebo_ros_control.so">
            <legacyMode>false</legacyMode>

        </plugin>
    </gazebo>
    <link name="base_link">
        <pose>0 0.1 0 0 0</pose>
        <inertial>
            <mass value="2"/>
            <origin rpy="0 0 0" xyz="0 0 0.1"/>
            <inertia ixx="0.02" ixy="0" ixz="0" iyy="0.02" iyz="0" izz="0.01"/>
        </inertial>
        <collision name="collision_chassis">
            <origin xyz="0 0 0.116" rpy="0 0 0" />
            <geometry>
                <cylinder radius="0.1" length="0.35"/>
            </geometry>
        </collision>
        <visual name="chassis">
            <origin xyz="0 0 0.15" rpy="0 0 0" />
            <geometry>
                <cylinder radius="0.1" length="0.3"/>
            </geometry>    
            <material name="green" />
        </visual>

        <visual name="front_castor">
            <origin xyz="0.065 0 -0.025" rpy="0 0 0" />
            <geometry>
                <cylinder radius="0.025" length="0.05"/>
            </geometry>
        </visual>

        <visual name="back_castor" >
            <origin xyz="-0.065 0 -0.025" rpy="0 0 0" />
            <geometry>
                <cylinder radius="0.025" length="0.05"/>
            </geometry>
        </visual>
        
    </link>

    <link   name="base_footprint"/>


    <joint name = "base_joint"  type = "fixed">
        <parent link="base_footprint"/>
        <child link="base_link"/>
        <origin xyz="0.0 0.0 0.09188" rpy="0 0 0" />
        <axis xyz="0 1 0" rpy="0 0 0" />
    </joint>


    <link name="left_wheel_link">
        <inertial>
            <mass value="0.2"/>
            <origin rpy="0 1.5707 1.5707" xyz="0 0 0"/>
            <inertia ixx="0.000247" ixy="0" ixz="0" iyy="0.000247" iyz="0" izz="0.00016"/>
        </inertial>
        <collision name="left_wheel_link_collision">
            <origin rpy="0 1.5707 1.5707" xyz="0 0 0"/>
            <geometry>
                <cylinder radius="0.04" length="0.01"/>
            </geometry>
        </collision>
        <visual name="left_wheel" >
            <origin xyz="0 0 0" rpy="0 1.5707 1.5707" />
            <geometry>
                <cylinder radius="0.04" length="0.01"/>
            </geometry>
        </visual>
    </link>
    

    <link name="right_wheel_link">
        <inertial>
            <mass value="0.2"/>
            <origin rpy="0 1.5707 1.5707" xyz="0 0 0"/>
            <inertia ixx="0.000247" ixy="0" ixz="0" iyy=" 0.000247" iyz="0" izz="0.00016"/>
        </inertial>
        <collision name="right_wheel_link_collision">
            <origin rpy="0 1.5707 1.5707" xyz="0 0 0"/>
            <geometry>
                <cylinder radius="0.04" length="0.01"/>
            </geometry>
        </collision>
        <visual name="right_wheel" >
            <origin xyz="0 0 0" rpy="0 1.5707 1.5707" />
            <geometry>
                <cylinder radius="0.04" length="0.01"/>
            </geometry>
        </visual>
    </link>


    <joint name="left_wheel_joint" type="continuous">
        <parent link="base_link"/>
        <child link="left_wheel_link"/>
        <origin xyz="0 0.11 -0.02" rpy="0 0 0"/>
        <axis xyz="0 1 0" rpy="0 0 0"/>
        <limit effort="0.4" velocity="0.299"/>
        <joint_properties damping="1.0" friction="1.0" />
    </joint>

    <joint name="right_wheel_joint" type="continuous">
        <parent link="base_link"/>
        <child link="right_wheel_link"/>
        <origin xyz="0 -0.11 -0.02" rpy="0 0 0"/>
        <axis xyz="0 1 0" rpy="0 0 0"/>
        <limit effort="0.4" velocity="0.299"/>
        <joint_properties damping="1.0" friction="1.0" />
    </joint>

    <transmission name="left_wheel_joint_trans" type="SimpleTransmission">
        <type>transmission_interface/SimpleTransmission</type>
        <joint name="left_wheel_joint">
            <hardwareInterface>hardware_interface/VelocityJointInterface</hardwareInterface>
        </joint>
        <actuator name="left_wheel_joint_motor">
            <hardwareInterface>hardware_interface/VelocityJointInterface</hardwareInterface>
            <mechanicalReduction>1</mechanicalReduction>
        </actuator>
    </transmission>

    <transmission name="right_wheel_joint_trans" type="SimpleTransmission">
        <type>transmission_interface/SimpleTransmission</type>
        <joint name="right_wheel_joint">
            <hardwareInterface>hardware_interface/VelocityJointInterface</hardwareInterface>
        </joint>
        <actuator name="right_wheel_joint_motor">
            <hardwareInterface>hardware_interface/VelocityJointInterface</hardwareInterface>
            <mechanicalReduction>1</mechanicalReduction>
        </actuator>
    </transmission>
</robot>